[0m13:29:18.256708 [debug] [MainThread]: Sending event: {'category': 'dbt', 'action': 'invocation', 'label': 'start', 'context': [<snowplow_tracker.self_describing_json.SelfDescribingJson object at 0x000001AEDD986660>, <snowplow_tracker.self_describing_json.SelfDescribingJson object at 0x000001AEDA90DBD0>, <snowplow_tracker.self_describing_json.SelfDescribingJson object at 0x000001AEDF339450>]}


============================== 13:29:18.293239 | f2048ea0-13e3-49b9-abeb-2217c518d54a ==============================
[0m13:29:18.293239 [info ] [MainThread]: Running with dbt=1.9.8
[0m13:29:18.296843 [debug] [MainThread]: running dbt with arguments {'printer_width': '80', 'indirect_selection': 'eager', 'log_cache_events': 'False', 'write_json': 'True', 'partial_parse': 'True', 'cache_selected_only': 'False', 'warn_error': 'None', 'debug': 'False', 'version_check': 'True', 'log_path': 'logs', 'profiles_dir': 'C:\\Users\\marzo\\.dbt', 'fail_fast': 'False', 'use_colors': 'True', 'use_experimental_parser': 'False', 'no_print': 'None', 'quiet': 'False', 'empty': 'None', 'warn_error_options': 'WarnErrorOptions(include=[], exclude=[])', 'invocation_command': 'dbt init flix_project', 'log_format': 'default', 'introspect': 'True', 'target_path': 'None', 'static_parser': 'True', 'send_anonymous_usage_stats': 'True'}
[0m13:29:18.712163 [debug] [MainThread]: Starter project path: C:\Users\marzo\dbt-env\Lib\site-packages\dbt\include\starter_project
[0m13:29:18.766347 [info ] [MainThread]: 
Your new dbt project "flix_project" was created!

For more information on how to configure the profiles.yml file,
please consult the dbt documentation here:

  https://docs.getdbt.com/docs/configure-your-profile

One more thing:

Need help? Don't hesitate to reach out to us via GitHub issues or on Slack:

  https://community.getdbt.com/

Happy modeling!

[0m13:29:18.767717 [info ] [MainThread]: Setting up your profile.
[0m13:29:36.248357 [error] [MainThread]: Encountered an error:
list index out of range
[0m13:29:36.314942 [error] [MainThread]: Traceback (most recent call last):
  File "C:\Users\marzo\dbt-env\Lib\site-packages\dbt\cli\requires.py", line 153, in wrapper
    result, success = func(*args, **kwargs)
                      ~~~~^^^^^^^^^^^^^^^^^
  File "C:\Users\marzo\dbt-env\Lib\site-packages\dbt\cli\requires.py", line 103, in wrapper
    return func(*args, **kwargs)
  File "C:\Users\marzo\dbt-env\Lib\site-packages\dbt\cli\main.py", line 477, in init
    results = task.run()
  File "C:\Users\marzo\dbt-env\Lib\site-packages\dbt\task\init.py", line 346, in run
    self.setup_profile(profile_name)
    ~~~~~~~~~~~~~~~~~~^^^^^^^^^^^^^^
  File "C:\Users\marzo\dbt-env\Lib\site-packages\dbt\task\init.py", line 261, in setup_profile
    adapter = self.ask_for_adapter_choice()
  File "C:\Users\marzo\dbt-env\Lib\site-packages\dbt\task\init.py", line 243, in ask_for_adapter_choice
    return available_adapters[numeric_choice - 1]
           ~~~~~~~~~~~~~~~~~~^^^^^^^^^^^^^^^^^^^^
IndexError: list index out of range

[0m13:29:36.316127 [debug] [MainThread]: Command `dbt init` failed at 13:29:36.315953 after 18.39 seconds
[0m13:29:36.316664 [debug] [MainThread]: Sending event: {'category': 'dbt', 'action': 'invocation', 'label': 'end', 'context': [<snowplow_tracker.self_describing_json.SelfDescribingJson object at 0x000001AEDF86CFC0>, <snowplow_tracker.self_describing_json.SelfDescribingJson object at 0x000001AEDF8A85F0>, <snowplow_tracker.self_describing_json.SelfDescribingJson object at 0x000001AEDF657130>]}
[0m13:29:36.317265 [debug] [MainThread]: Flushing usage events
[0m13:29:36.861710 [debug] [MainThread]: An error was encountered while trying to flush usage events
[0m16:14:07.704663 [debug] [MainThread]: Sending event: {'category': 'dbt', 'action': 'invocation', 'label': 'start', 'context': [<snowplow_tracker.self_describing_json.SelfDescribingJson object at 0x0000016296666660>, <snowplow_tracker.self_describing_json.SelfDescribingJson object at 0x00000162935A9BD0>, <snowplow_tracker.self_describing_json.SelfDescribingJson object at 0x0000016296F39450>]}


============================== 16:14:07.724627 | 3bfff16a-8781-4138-8d69-f54175aa60b8 ==============================
[0m16:14:07.724627 [info ] [MainThread]: Running with dbt=1.9.8
[0m16:14:07.725662 [debug] [MainThread]: running dbt with arguments {'printer_width': '80', 'indirect_selection': 'eager', 'log_cache_events': 'False', 'write_json': 'True', 'partial_parse': 'True', 'cache_selected_only': 'False', 'warn_error': 'None', 'debug': 'False', 'profiles_dir': 'C:\\Users\\marzo\\.dbt', 'log_path': 'logs', 'version_check': 'True', 'fail_fast': 'False', 'use_colors': 'True', 'use_experimental_parser': 'False', 'no_print': 'None', 'quiet': 'False', 'empty': 'None', 'log_format': 'default', 'static_parser': 'True', 'introspect': 'True', 'invocation_command': 'dbt test', 'target_path': 'None', 'warn_error_options': 'WarnErrorOptions(include=[], exclude=[])', 'send_anonymous_usage_stats': 'True'}
[0m16:14:07.726280 [error] [MainThread]: Encountered an error:
Runtime Error
  No dbt_project.yml found at expected path C:\Users\marzo\flix_project\dbt_project.yml
  Verify that each entry within packages.yml (and their transitive dependencies) contains a file named dbt_project.yml
  
[0m16:14:07.727538 [debug] [MainThread]: Command `dbt test` failed at 16:14:07.727357 after 0.34 seconds
[0m16:14:07.728033 [debug] [MainThread]: Sending event: {'category': 'dbt', 'action': 'invocation', 'label': 'end', 'context': [<snowplow_tracker.self_describing_json.SelfDescribingJson object at 0x000001629828F950>, <snowplow_tracker.self_describing_json.SelfDescribingJson object at 0x000001629844C4D0>, <snowplow_tracker.self_describing_json.SelfDescribingJson object at 0x0000016298256690>]}
[0m16:14:07.728534 [debug] [MainThread]: Flushing usage events
[0m16:14:08.265959 [debug] [MainThread]: An error was encountered while trying to flush usage events
[0m16:47:13.648813 [debug] [MainThread]: Sending event: {'category': 'dbt', 'action': 'invocation', 'label': 'start', 'context': [<snowplow_tracker.self_describing_json.SelfDescribingJson object at 0x000001BBF9546660>, <snowplow_tracker.self_describing_json.SelfDescribingJson object at 0x000001BBF7489BD0>, <snowplow_tracker.self_describing_json.SelfDescribingJson object at 0x000001BBF9E39450>]}


============================== 16:47:13.667505 | ed18e96f-accc-475d-a2ad-8f9e7201ea01 ==============================
[0m16:47:13.667505 [info ] [MainThread]: Running with dbt=1.9.8
[0m16:47:13.670334 [debug] [MainThread]: running dbt with arguments {'printer_width': '80', 'indirect_selection': 'eager', 'log_cache_events': 'False', 'write_json': 'True', 'partial_parse': 'True', 'cache_selected_only': 'False', 'warn_error': 'None', 'version_check': 'True', 'profiles_dir': 'C:\\Users\\marzo\\.dbt', 'log_path': 'logs', 'debug': 'False', 'fail_fast': 'False', 'use_colors': 'True', 'use_experimental_parser': 'False', 'no_print': 'None', 'quiet': 'False', 'empty': 'None', 'warn_error_options': 'WarnErrorOptions(include=[], exclude=[])', 'introspect': 'True', 'static_parser': 'True', 'invocation_command': 'dbt test', 'target_path': 'None', 'log_format': 'default', 'send_anonymous_usage_stats': 'True'}
[0m16:47:13.671524 [error] [MainThread]: Encountered an error:
Runtime Error
  No dbt_project.yml found at expected path C:\Users\marzo\flix_project\dbt_project.yml
  Verify that each entry within packages.yml (and their transitive dependencies) contains a file named dbt_project.yml
  
[0m16:47:13.674661 [debug] [MainThread]: Command `dbt test` failed at 16:47:13.674234 after 0.37 seconds
[0m16:47:13.675526 [debug] [MainThread]: Sending event: {'category': 'dbt', 'action': 'invocation', 'label': 'end', 'context': [<snowplow_tracker.self_describing_json.SelfDescribingJson object at 0x000001BBFB18F950>, <snowplow_tracker.self_describing_json.SelfDescribingJson object at 0x000001BBFB34C4D0>, <snowplow_tracker.self_describing_json.SelfDescribingJson object at 0x000001BBFB156690>]}
[0m16:47:13.676373 [debug] [MainThread]: Flushing usage events
[0m16:47:14.238750 [debug] [MainThread]: An error was encountered while trying to flush usage events
[0m16:49:26.010969 [debug] [MainThread]: Sending event: {'category': 'dbt', 'action': 'invocation', 'label': 'start', 'context': [<snowplow_tracker.self_describing_json.SelfDescribingJson object at 0x0000021565B46660>, <snowplow_tracker.self_describing_json.SelfDescribingJson object at 0x0000021562A75BD0>, <snowplow_tracker.self_describing_json.SelfDescribingJson object at 0x000002156743D450>]}


============================== 16:49:26.019229 | 5382fbde-423f-4499-9bcf-18bf7a442da5 ==============================
[0m16:49:26.019229 [info ] [MainThread]: Running with dbt=1.9.8
[0m16:49:26.020866 [debug] [MainThread]: running dbt with arguments {'printer_width': '80', 'indirect_selection': 'eager', 'write_json': 'True', 'log_cache_events': 'False', 'partial_parse': 'True', 'cache_selected_only': 'False', 'profiles_dir': 'C:\\Users\\marzo\\.dbt', 'fail_fast': 'False', 'debug': 'False', 'log_path': 'logs', 'warn_error': 'None', 'version_check': 'True', 'use_colors': 'True', 'use_experimental_parser': 'False', 'empty': 'None', 'quiet': 'False', 'no_print': 'None', 'warn_error_options': 'WarnErrorOptions(include=[], exclude=[])', 'static_parser': 'True', 'log_format': 'default', 'invocation_command': 'dbt test', 'target_path': 'None', 'introspect': 'True', 'send_anonymous_usage_stats': 'True'}
[0m16:49:26.021931 [error] [MainThread]: Encountered an error:
Runtime Error
  No dbt_project.yml found at expected path C:\Users\marzo\flix_project\dbt_project.yml
  Verify that each entry within packages.yml (and their transitive dependencies) contains a file named dbt_project.yml
  
[0m16:49:26.025423 [debug] [MainThread]: Command `dbt test` failed at 16:49:26.025134 after 0.32 seconds
[0m16:49:26.026179 [debug] [MainThread]: Sending event: {'category': 'dbt', 'action': 'invocation', 'label': 'end', 'context': [<snowplow_tracker.self_describing_json.SelfDescribingJson object at 0x000002156778F950>, <snowplow_tracker.self_describing_json.SelfDescribingJson object at 0x000002156794C4D0>, <snowplow_tracker.self_describing_json.SelfDescribingJson object at 0x0000021567756690>]}
[0m16:49:26.026948 [debug] [MainThread]: Flushing usage events
[0m16:49:26.551090 [debug] [MainThread]: An error was encountered while trying to flush usage events
[0m16:49:33.044296 [debug] [MainThread]: Sending event: {'category': 'dbt', 'action': 'invocation', 'label': 'start', 'context': [<snowplow_tracker.self_describing_json.SelfDescribingJson object at 0x00000181DEB86660>, <snowplow_tracker.self_describing_json.SelfDescribingJson object at 0x00000181DBB0DBD0>, <snowplow_tracker.self_describing_json.SelfDescribingJson object at 0x00000181E051D450>]}


============================== 16:49:33.049778 | 986c0129-5f8d-41ba-a27a-d4250fbe7621 ==============================
[0m16:49:33.049778 [info ] [MainThread]: Running with dbt=1.9.8
[0m16:49:33.050831 [debug] [MainThread]: running dbt with arguments {'printer_width': '80', 'indirect_selection': 'eager', 'write_json': 'True', 'log_cache_events': 'False', 'partial_parse': 'True', 'cache_selected_only': 'False', 'profiles_dir': 'C:\\Users\\marzo\\.dbt', 'debug': 'False', 'version_check': 'True', 'log_path': 'logs', 'fail_fast': 'False', 'warn_error': 'None', 'use_colors': 'True', 'use_experimental_parser': 'False', 'empty': 'None', 'quiet': 'False', 'no_print': 'None', 'warn_error_options': 'WarnErrorOptions(include=[], exclude=[])', 'invocation_command': 'dbt test', 'introspect': 'True', 'static_parser': 'True', 'target_path': 'None', 'log_format': 'default', 'send_anonymous_usage_stats': 'True'}
[0m16:49:33.051676 [error] [MainThread]: Encountered an error:
Runtime Error
  No dbt_project.yml found at expected path C:\Users\marzo\flix_project\dbt_project.yml
  Verify that each entry within packages.yml (and their transitive dependencies) contains a file named dbt_project.yml
  
[0m16:49:33.052882 [debug] [MainThread]: Command `dbt test` failed at 16:49:33.052728 after 0.15 seconds
[0m16:49:33.053310 [debug] [MainThread]: Sending event: {'category': 'dbt', 'action': 'invocation', 'label': 'end', 'context': [<snowplow_tracker.self_describing_json.SelfDescribingJson object at 0x00000181E088F950>, <snowplow_tracker.self_describing_json.SelfDescribingJson object at 0x00000181E0A4C4D0>, <snowplow_tracker.self_describing_json.SelfDescribingJson object at 0x00000181E0856690>]}
[0m16:49:33.053686 [debug] [MainThread]: Flushing usage events
[0m16:49:33.551088 [debug] [MainThread]: An error was encountered while trying to flush usage events
